Workbook
Name Slicer_Manager: #N/A
Name Slicer_Project: #N/A

Sheet Data
A1: Project | B1: Task | C1: Manager | D1: Start Date | E1: Duration | F1: End Date | G1: Days completed | H1: Progress | I1: Budget | J1: Actual
A2: Gemini | B2: Task 1 | C2: Hirsch | D2: 43878 | E2: 5 | F2: =WORKDAY.INTL(Table1[[#This Row],[Start Date]]-1,Table1[[#This Row],[Duration]],1) -> 43882 | G2: 2 | H2: =Table1[[#This Row],[Days completed]]/Table1[[#This Row],[Duration]] -> 0.4 | I2: 218000 | J2: 97337
A3: Gemini | B3: Task 2 | C3: Samora | D3: 43878 | E3: 6 | F3: =WORKDAY.INTL(Table1[[#This Row],[Start Date]]-1,Table1[[#This Row],[Duration]],1) -> 43885 | G3: 3 | H3: =Table1[[#This Row],[Days completed]]/Table1[[#This Row],[Duration]] -> 0.5 | I3: 393000 | J3: 177440
A4: Gemini | B4: Task 3 | C4: McFay | D4: 43879 | E4: 10 | F4: =WORKDAY.INTL(Table1[[#This Row],[Start Date]]-1,Table1[[#This Row],[Duration]],1) -> 43892 | G4: 4 | H4: =Table1[[#This Row],[Days completed]]/Table1[[#This Row],[Duration]] -> 0.4 | I4: 86000 | J4: 31046
A5: Gemini | B5: Task 4 | C5: Wood | D5: 43882 | E5: 9 | F5: =WORKDAY.INTL(Table1[[#This Row],[Start Date]]-1,Table1[[#This Row],[Duration]],1) -> 43894 | G5: 3 | H5: =Table1[[#This Row],[Days completed]]/Table1[[#This Row],[Duration]] -> 0.33333333 | I5: 732000 | J5: 261324
A6: Gemini | B6: Task 5 | C6: Ladd | D6: 43878 | E6: 4 | F6: =WORKDAY.INTL(Table1[[#This Row],[Start Date]]-1,Table1[[#This Row],[Duration]],1) -> 43881 | G6: 1 | H6: =Table1[[#This Row],[Days completed]]/Table1[[#This Row],[Duration]] -> 0.25 | I6: 492000 | J6: 116850
A7: Gemini | B7: Task 6 | C7: Hirsch | D7: 43881 | E7: 6 | F7: =WORKDAY.INTL(Table1[[#This Row],[Start Date]]-1,Table1[[#This Row],[Duration]],1) -> 43888 | G7: 0 | H7: =Table1[[#This Row],[Days completed]]/Table1[[#This Row],[Duration]] -> 0 | I7: 188000 | J7: 0
A8: Gemini | B8: Task 7 | C8: Samora | D8: 43881 | E8: 7 | F8: =WORKDAY.INTL(Table1[[#This Row],[Start Date]]-1,Table1[[#This Row],[Duration]],1) -> 43889 | G8: 3 | H8: =Table1[[#This Row],[Days completed]]/Table1[[#This Row],[Duration]] -> 0.42857143 | I8: 180000 | J8: 79380
A9: Gemini | B9: Task 8 | C9: McFay | D9: 43885 | E9: 5 | F9: =WORKDAY.INTL(Table1[[#This Row],[Start Date]]-1,Table1[[#This Row],[Duration]],1) -> 43889 | G9: 2 | H9: =Table1[[#This Row],[Days completed]]/Table1[[#This Row],[Duration]] -> 0.4 | I9: 582000 | J9: 195231
A10: Gemini | B10: Task 9 | C10: Wood | D10: 43885 | E10: 9 | F10: =WORKDAY.INTL(Table1[[#This Row],[Start Date]]-1,Table1[[#This Row],[Duration]],1) -> 43895 | G10: 1 | H10: =Table1[[#This Row],[Days completed]]/Table1[[#This Row],[Duration]] -> 0.11111111 | I10: 562000 | J10: 74746
A11: Gemini | B11: Task 10 | C11: Ladd | D11: 43885 | E11: 6 | F11: =WORKDAY.INTL(Table1[[#This Row],[Start Date]]-1,Table1[[#This Row],[Duration]],1) -> 43892 | G11: 3 | H11: =Table1[[#This Row],[Days completed]]/Table1[[#This Row],[Duration]] -> 0.5 | I11: 416000 | J11: 175015
A12: Orion | B12: Task 1 | C12: Hirsch | D12: 43879 | E12: 7 | F12: =WORKDAY.INTL(Table1[[#This Row],[Start Date]]-1,Table1[[#This Row],[Duration]],1) -> 43887 | G12: 7 | H12: =Table1[[#This Row],[Days completed]]/Table1[[#This Row],[Duration]] -> 1 | I12: 293000 | J12: 273001
A13: Orion | B13: Task 2 | C13: Samora | D13: 43878 | E13: 9 | F13: =WORKDAY.INTL(Table1[[#This Row],[Start Date]]-1,Table1[[#This Row],[Duration]],1) -> 43888 | G13: 4 | H13: =Table1[[#This Row],[Days completed]]/Table1[[#This Row],[Duration]] -> 0.44444444 | I13: 224000 | J13: 57910
... A41: Alpha | B41: Task 8 | C41: Ladd | D41: 43885 | E41: 3 | F41: =WORKDAY.INTL(Table1[[#This Row],[Start Date]]-1,Table1[[#This Row],[Duration]],1) -> 43887 | G41: 0 | H41: =Table1[[#This Row],[Days completed]]/Table1[[#This Row],[Duration]] -> 0 | I41: 691000 | J41: 0

Sheet Workings
A1: Budget v Actual Doughnut & Bar Chart | E1: Tasks Bar Chart | I1: Overall Progress - Days Completed v Duration Doughnut Chart | P1: Scroll bar position
B2: Actual | C2: Budget | E2: Not Started | F2: =COUNTIF(Dashboard!H6:H51,"="&0) -> 4 | G2: =_xlfn.FORMULATEXT(F2) -> =COUNTIF(Dashboard!H6:H51,"="&0) | I2: Values | L2: Doughnut Chart | M2: % | N2: Formula | P2: 0
A3: Bar Chart | B3: 8340291 | C3: 19695000 | E3: In Progress | F3: =COUNTIFS(Dashboard!H6:H51,"<>"&0,Dashboard!H6:H51,"<"&1) -> 33 | G3: =_xlfn.FORMULATEXT(F3) -> =COUNTIFS(Dashboard!H6:H51,"<>"&0,Dashboard!H6:H51,"<"&1) | I3: Days completed | J3: 112 | L3: Days Completed | M3: =J3/$J$4 -> 0.42105263 | N3: =_xlfn.FORMULATEXT(M3) -> =J3/$J$4
A4: Dougnut Chart | B4: =GETPIVOTDATA("Actual ",$B$2)/GETPIVOTDATA("Budget ",$B$2) -> 0.42347251 | C4: =1-B4 -> 0.57652749 | E4: Completed | F4: =COUNTIF(Dashboard!H6:H51,"="&1) -> 3 | G4: =_xlfn.FORMULATEXT(F4) -> =COUNTIF(Dashboard!H6:H51,"="&1) | I4: Duration | J4: 266 | L4: Days Remaining | M4: =1-M3 -> 0.57894737 | N4: =_xlfn.FORMULATEXT(M4) -> =1-M3
C5: =_xlfn.FORMULATEXT(C4) -> =1-B4 | E5: Remaining | F5: =F3+F2 -> 37 | G5: =_xlfn.FORMULATEXT(F5) -> =F3+F2
E6: Total Tasks | F6: =COUNTA(Dashboard!B6:B50) -> 40 | G6: =_xlfn.FORMULATEXT(F6) -> =COUNTA(Dashboard!B6:B50)

Sheet Dashboard
A1: Project Management Dashboard | F1: =TEXT(MIN(D6:D51),"d-mmm-yy")&" to "&TEXT(MAX(E6:E51),"d-mmm-yy") -> 17-Feb-20 to 13-Mar-20
A5: Project | B5: Task | C5: Manager | D5: Start Date | E5: End Date | F5: Duration | G5: Days comp. | H5: Progress | I5: Budget | J5: Actual | K5: {=_xlfn.SEQUENCE(1,26,MIN(Table1[Start Date])+Workings!P2,1)} -> 43878 | L5: 43879 | M5: 43880 | N5: 43881 | O5: 43882 | P5: 43883 | Q5: 43884 | R5: 43885 | S5: 43886 | T5: 43887 | U5: 43888 | V5: 43889 | W5: 43890 | X5: 43891 | Y5: 43892 | Z5: 43893 | AA5: 43894 | AB5: 43895 | AC5: 43896 | AD5: 43897 | AE5: 43898 | AF5: 43899 | AG5: 43900 | AH5: 43901 | AI5: 43902 | AJ5: 43903
A6: Alpha | B6: Task 1 | C6: McFay | D6: 43889 | E6: 43900 | F6: 8 | G6: 3 | H6: 0.375 | I6: 96000 | J6: 32256
B7: Task 2 | C7: Wood | D7: 43892 | E7: 43902 | F7: 9 | G7: 4 | H7: 0.44444444 | I7: 513000 | J7: 226233
B8: Task 3 | C8: Ladd | D8: 43881 | E8: 43887 | F8: 5 | G8: 3 | H8: 0.6 | I8: 616000 | J8: 401579
B9: Task 4 | C9: Hirsch | D9: 43880 | E9: 43882 | F9: 3 | G9: 3 | H9: 1 | I9: 817000 | J9: 807069
B10: Task 5 | C10: Samora | D10: 43882 | E10: 43892 | F10: 7 | G10: 3 | H10: 0.42857143 | I10: 372000 | J10: 173166
B11: Task 6 | C11: McFay | D11: 43885 | E11: 43896 | F11: 10 | G11: 2 | H11: 0.2 | I11: 50000 | J11: 8400
B12: Task 7 | C12: Wood | D12: 43885 | E12: 43896 | F12: 10 | G12: 3 | H12: 0.3 | I12: 807000 | J12: 262679
B13: Task 8 | C13: Ladd | D13: 43885 | E13: 43887 | F13: 3 | G13: 0 | H13: 0 | I13: 691000 | J13: 0
A14: Delta | B14: Task 1 | C14: Hirsch | D14: 43892 | E14: 43902 | F14: 9 | G14: 8 | H14: 0.88888889 | I14: 787000 | J14: 727188
B15: Task 2 | C15: Samora | D15: 43892 | E15: 43903 | F15: 10 | G15: 2 | H15: 0.2 | I15: 228000 | J15: 47880
B16: Task 3 | C16: McFay | D16: 43878 | E16: 43881 | F16: 4 | G16: 0 | H16: 0 | I16: 147000 | J16: 0
B17: Task 4 | C17: Wood | D17: 43880 | E17: 43889 | F17: 8 | G17: 5 | H17: 0.625 | I17: 338000 | J17: 205123
B18: Task 5 | C18: Ladd | D18: 43885 | E18: 43896 | F18: 10 | G18: 3 | H18: 0.3 | I18: 857000 | J18: 305949
B19: Task 6 | C19: Hirsch | D19: 43886 | E19: 43893 | F19: 6 | G19: 3 | H19: 0.5 | I19: 602000 | J19: 322371
B20: Task 7 | C20: Samora | D20: 43886 | E20: 43889 | F20: 4 | G20: 2 | H20: 0.5 | I20: 990000 | J20: 451440
A21: Gemini | B21: Task 1 | C21: Hirsch | D21: 43878 | E21: 43882 | F21: 5 | G21: 2 | H21: 0.4 | I21: 218000 | J21: 97337
B22: Task 2 | C22: Samora | D22: 43878 | E22: 43885 | F22: 6 | G22: 3 | H22: 0.5 | I22: 393000 | J22: 177440
B23: Task 3 | C23: McFay | D23: 43879 | E23: 43892 | F23: 10 | G23: 4 | H23: 0.4 | I23: 86000 | J23: 31046
B24: Task 4 | C24: Wood | D24: 43882 | E24: 43894 | F24: 9 | G24: 3 | H24: 0.33333333 | I24: 732000 | J24: 261324
B25: Task 5 | C25: Ladd | D25: 43878 | E25: 43881 | F25: 4 | G25: 1 | H25: 0.25 | I25: 492000 | J25: 116850
B26: Task 6 | C26: Hirsch | D26: 43881 | E26: 43888 | F26: 6 | G26: 0 | H26: 0 | I26: 188000 | J26: 0
B27: Task 7 | C27: Samora | D27: 43881 | E27: 43889 | F27: 7 | G27: 3 | H27: 0.42857143 | I27: 180000 | J27: 79380
B28: Task 8 | C28: McFay | D28: 43885 | E28: 43889 | F28: 5 | G28: 2 | H28: 0.4 | I28: 582000 | J28: 195231
B29: Task 9 | C29: Wood | D29: 43885 | E29: 43895 | F29: 9 | G29: 1 | H29: 0.11111111 | I29: 562000 | J29: 74746
B30: Task 10 | C30: Ladd | D30: 43885 | E30: 43892 | F30: 6 | G30: 3 | H30: 0.5 | I30: 416000 | J30: 175015
A31: Orion | B31: Task 1 | C31: Hirsch | D31: 43879 | E31: 43887 | F31: 7 | G31: 7 | H31: 1 | I31: 293000 | J31: 273001
B32: Task 2 | C32: Samora | D32: 43878 | E32: 43888 | F32: 9 | G32: 4 | H32: 0.44444444 | I32: 224000 | J32: 57910
B33: Task 3 | C33: McFay | D33: 43879 | E33: 43888 | F33: 8 | G33: 0 | H33: 0 | I33: 978000 | J33: 0
B34: Task 4 | C34: Wood | D34: 43881 | E34: 43889 | F34: 7 | G34: 3 | H34: 0.42857143 | I34: 932000 | J34: 379157
B35: Task 5 | C35: Ladd | D35: 43882 | E35: 43887 | F35: 4 | G35: 1 | H35: 0.25 | I35: 854000 | J35: 322812
B36: Task 6 | C36: Hirsch | D36: 43882 | E36: 43889 | F36: 6 | G36: 3 | H36: 0.5 | I36: 81000 | J36: 38461
B37: Task 7 | C37: Samora | D37: 43885 | E37: 43892 | F37: 6 | G37: 5 | H37: 0.83333333 | I37: 169000 | J37: 136468
B38: Task 8 | C38: McFay | D38: 43886 | E38: 43889 | F38: 4 | G38: 1 | H38: 0.25 | I38: 61000 | J38: 12078
B39: Task 9 | C39: Wood | D39: 43888 | E39: 43896 | F39: 7 | G39: 3 | H39: 0.42857143 | I39: 645000 | J39: 273048
B40: Task 10 | C40: Ladd | D40: 43878 | E40: 43880 | F40: 3 | G40: 3 | H40: 1 | I40: 68000 | J40: 64987
A41: Vega | B41: Task 1 | C41: Hirsch | D41: 43878 | E41: 43889 | F41: 10 | G41: 5 | H41: 0.5 | I41: 839000 | J41: 406974
B42: Task 2 | C42: Samora | D42: 43882 | E42: 43888 | F42: 5 | G42: 4 | H42: 0.8 | I42: 729000 | J42: 487139
B43: Task 3 | C43: McFay | D43: 43885 | E43: 43893 | F43: 7 | G43: 3 | H43: 0.42857143 | I43: 826000 | J43: 298186
...
